{
  "timestamp": "2025-09-11T15:09:54.254Z",
  "totalRules": 14,
  "passed": 0,
  "warnings": 14,
  "failed": 0,
  "details": {
    "passed": [],
    "failed": [],
    "warnings": [
      {
        "rule": "basic-cfg.yml",
        "error": "Command failed: semgrep --config=D:\\ide\\tool\\codebase-index\\enhanced-rules\\control-flow\\basic-cfg.yml D:\\ide\\tool\\codebase-index\\test\\enhanced-semgrep\\test-basic-cfg.js --json\n[00.08][WARNING](ca-certs): Ignored 1 trust anchors.\r\n'gbk' codec can't decode byte 0xaa in position 491: illegal multibyte sequence\r\nTraceback (most recent call last):\r\n  File \"C:\\Users\\33530\\anaconda3\\Lib\\site-packages\\semgrep\\commands\\wrapper.py\", line 51, in wrapper\r\n    func(*args, **kwargs)\r\n  File \"C:\\Users\\33530\\anaconda3\\Lib\\site-packages\\semgrep\\commands\\scan.py\", line 962, in scan\r\n    ) = semgrep.run_scan.run_scan(\r\n        ^^^^^^^^^^^^^^^^^^^^^^^^^^\r\n  File \"C:\\Users\\33530\\anaconda3\\Lib\\site-packages\\semgrep\\tracing.py\", line 294, in inner\r\n    return f(*args, **kwargs)\r\n           ^^^^^^^^^^^^^^^^^^\r\n  File \"C:\\Users\\33530\\anaconda3\\Lib\\site-packages\\semgrep\\run_scan.py\", line 1102, in run_scan\r\n    configs_obj, config_errors = get_config(\r\n                                 ^^^^^^^^^^^\r\n  File \"C:\\Users\\33530\\anaconda3\\Lib\\site-packages\\semgrep\\tracing.py\", line 294, in inner\r\n    return f(*args, **kwargs)\r\n           ^^^^^^^^^^^^^^^^^^\r\n  File \"C:\\Users\\33530\\anaconda3\\Lib\\site-packages\\semgrep\\config_resolver.py\", line 1053, in get_config\r\n    config, errors = Config.from_config_list(\r\n                     ^^^^^^^^^^^^^^^^^^^^^^^^\r\n  File \"C:\\Users\\33530\\anaconda3\\Lib\\site-packages\\semgrep\\tracing.py\", line 294, in inner\r\n    return f(*args, **kwargs)\r\n           ^^^^^^^^^^^^^^^^^^\r\n  File \"C:\\Users\\33530\\anaconda3\\Lib\\site-packages\\semgrep\\config_resolver.py\", line 631, in from_config_list\r\n    resolved_config, config_errors = resolve_config(\r\n                                     ^^^^^^^^^^^^^^^\r\n  File \"C:\\Users\\33530\\anaconda3\\Lib\\site-packages\\semgrep\\tracing.py\", line 294, in inner\r\n    return f(*args, **kwargs)\r\n           ^^^^^^^^^^^^^^^^^^\r\n  File \"C:\\Users\\33530\\anaconda3\\Lib\\site-packages\\semgrep\\config_resolver.py\", line 535, in resolve_config\r\n    config_loader.load_config(),\r\n    ^^^^^^^^^^^^^^^^^^^^^^^^^^^\r\n  File \"C:\\Users\\33530\\anaconda3\\Lib\\site-packages\\semgrep\\config_resolver.py\", line 166, in load_config\r\n    return self._load_config_from_local_path()\r\n           ^^^^^^^^^^^^^^^^^^^^^^^^^^^^^^^^^^^\r\n  File \"C:\\Users\\33530\\anaconda3\\Lib\\site-packages\\semgrep\\config_resolver.py\", line 231, in _load_config_from_local_path\r\n    config = [read_config_at_path(loc)]\r\n              ^^^^^^^^^^^^^^^^^^^^^^^^\r\n  File \"C:\\Users\\33530\\anaconda3\\Lib\\site-packages\\semgrep\\config_resolver.py\", line 409, in read_config_at_path\r\n    return ConfigFile(config_id, loc.read_text(), str(loc))\r\n                                 ^^^^^^^^^^^^^^^\r\n  File \"C:\\Users\\33530\\anaconda3\\Lib\\pathlib.py\", line 1028, in read_text\r\n    return f.read()\r\n           ^^^^^^^^\r\nUnicodeDecodeError: 'gbk' codec can't decode byte 0xaa in position 491: illegal multibyte sequence\r\n"
      },
      {
        "rule": "cross-function-analysis.yml",
        "error": "Command failed: semgrep --config=D:\\ide\\tool\\codebase-index\\enhanced-rules\\control-flow\\cross-function-analysis.yml D:\\ide\\tool\\codebase-index\\test\\enhanced-semgrep\\test-cross-function-analysis.js --json\n[00.08][WARNING](ca-certs): Ignored 1 trust anchors.\r\n'gbk' codec can't decode byte 0xae in position 273: illegal multibyte sequence\r\nTraceback (most recent call last):\r\n  File \"C:\\Users\\33530\\anaconda3\\Lib\\site-packages\\semgrep\\commands\\wrapper.py\", line 51, in wrapper\r\n    func(*args, **kwargs)\r\n  File \"C:\\Users\\33530\\anaconda3\\Lib\\site-packages\\semgrep\\commands\\scan.py\", line 962, in scan\r\n    ) = semgrep.run_scan.run_scan(\r\n        ^^^^^^^^^^^^^^^^^^^^^^^^^^\r\n  File \"C:\\Users\\33530\\anaconda3\\Lib\\site-packages\\semgrep\\tracing.py\", line 294, in inner\r\n    return f(*args, **kwargs)\r\n           ^^^^^^^^^^^^^^^^^^\r\n  File \"C:\\Users\\33530\\anaconda3\\Lib\\site-packages\\semgrep\\run_scan.py\", line 1102, in run_scan\r\n    configs_obj, config_errors = get_config(\r\n                                 ^^^^^^^^^^^\r\n  File \"C:\\Users\\33530\\anaconda3\\Lib\\site-packages\\semgrep\\tracing.py\", line 294, in inner\r\n    return f(*args, **kwargs)\r\n           ^^^^^^^^^^^^^^^^^^\r\n  File \"C:\\Users\\33530\\anaconda3\\Lib\\site-packages\\semgrep\\config_resolver.py\", line 1053, in get_config\r\n    config, errors = Config.from_config_list(\r\n                     ^^^^^^^^^^^^^^^^^^^^^^^^\r\n  File \"C:\\Users\\33530\\anaconda3\\Lib\\site-packages\\semgrep\\tracing.py\", line 294, in inner\r\n    return f(*args, **kwargs)\r\n           ^^^^^^^^^^^^^^^^^^\r\n  File \"C:\\Users\\33530\\anaconda3\\Lib\\site-packages\\semgrep\\config_resolver.py\", line 631, in from_config_list\r\n    resolved_config, config_errors = resolve_config(\r\n                                     ^^^^^^^^^^^^^^^\r\n  File \"C:\\Users\\33530\\anaconda3\\Lib\\site-packages\\semgrep\\tracing.py\", line 294, in inner\r\n    return f(*args, **kwargs)\r\n           ^^^^^^^^^^^^^^^^^^\r\n  File \"C:\\Users\\33530\\anaconda3\\Lib\\site-packages\\semgrep\\config_resolver.py\", line 535, in resolve_config\r\n    config_loader.load_config(),\r\n    ^^^^^^^^^^^^^^^^^^^^^^^^^^^\r\n  File \"C:\\Users\\33530\\anaconda3\\Lib\\site-packages\\semgrep\\config_resolver.py\", line 166, in load_config\r\n    return self._load_config_from_local_path()\r\n           ^^^^^^^^^^^^^^^^^^^^^^^^^^^^^^^^^^^\r\n  File \"C:\\Users\\33530\\anaconda3\\Lib\\site-packages\\semgrep\\config_resolver.py\", line 231, in _load_config_from_local_path\r\n    config = [read_config_at_path(loc)]\r\n              ^^^^^^^^^^^^^^^^^^^^^^^^\r\n  File \"C:\\Users\\33530\\anaconda3\\Lib\\site-packages\\semgrep\\config_resolver.py\", line 409, in read_config_at_path\r\n    return ConfigFile(config_id, loc.read_text(), str(loc))\r\n                                 ^^^^^^^^^^^^^^^\r\n  File \"C:\\Users\\33530\\anaconda3\\Lib\\pathlib.py\", line 1028, in read_text\r\n    return f.read()\r\n           ^^^^^^^^\r\nUnicodeDecodeError: 'gbk' codec can't decode byte 0xae in position 273: illegal multibyte sequence\r\n"
      },
      {
        "rule": "enhanced-cfg-analysis.yml",
        "error": "Command failed: semgrep --config=D:\\ide\\tool\\codebase-index\\enhanced-rules\\control-flow\\enhanced-cfg-analysis.yml D:\\ide\\tool\\codebase-index\\test\\enhanced-semgrep\\test-enhanced-cfg-analysis.js --json\n[00.07][WARNING](ca-certs): Ignored 1 trust anchors.\r\n'gbk' codec can't decode byte 0xa5 in position 65: illegal multibyte sequence\r\nTraceback (most recent call last):\r\n  File \"C:\\Users\\33530\\anaconda3\\Lib\\site-packages\\semgrep\\commands\\wrapper.py\", line 51, in wrapper\r\n    func(*args, **kwargs)\r\n  File \"C:\\Users\\33530\\anaconda3\\Lib\\site-packages\\semgrep\\commands\\scan.py\", line 962, in scan\r\n    ) = semgrep.run_scan.run_scan(\r\n        ^^^^^^^^^^^^^^^^^^^^^^^^^^\r\n  File \"C:\\Users\\33530\\anaconda3\\Lib\\site-packages\\semgrep\\tracing.py\", line 294, in inner\r\n    return f(*args, **kwargs)\r\n           ^^^^^^^^^^^^^^^^^^\r\n  File \"C:\\Users\\33530\\anaconda3\\Lib\\site-packages\\semgrep\\run_scan.py\", line 1102, in run_scan\r\n    configs_obj, config_errors = get_config(\r\n                                 ^^^^^^^^^^^\r\n  File \"C:\\Users\\33530\\anaconda3\\Lib\\site-packages\\semgrep\\tracing.py\", line 294, in inner\r\n    return f(*args, **kwargs)\r\n           ^^^^^^^^^^^^^^^^^^\r\n  File \"C:\\Users\\33530\\anaconda3\\Lib\\site-packages\\semgrep\\config_resolver.py\", line 1053, in get_config\r\n    config, errors = Config.from_config_list(\r\n                     ^^^^^^^^^^^^^^^^^^^^^^^^\r\n  File \"C:\\Users\\33530\\anaconda3\\Lib\\site-packages\\semgrep\\tracing.py\", line 294, in inner\r\n    return f(*args, **kwargs)\r\n           ^^^^^^^^^^^^^^^^^^\r\n  File \"C:\\Users\\33530\\anaconda3\\Lib\\site-packages\\semgrep\\config_resolver.py\", line 631, in from_config_list\r\n    resolved_config, config_errors = resolve_config(\r\n                                     ^^^^^^^^^^^^^^^\r\n  File \"C:\\Users\\33530\\anaconda3\\Lib\\site-packages\\semgrep\\tracing.py\", line 294, in inner\r\n    return f(*args, **kwargs)\r\n           ^^^^^^^^^^^^^^^^^^\r\n  File \"C:\\Users\\33530\\anaconda3\\Lib\\site-packages\\semgrep\\config_resolver.py\", line 535, in resolve_config\r\n    config_loader.load_config(),\r\n    ^^^^^^^^^^^^^^^^^^^^^^^^^^^\r\n  File \"C:\\Users\\33530\\anaconda3\\Lib\\site-packages\\semgrep\\config_resolver.py\", line 166, in load_config\r\n    return self._load_config_from_local_path()\r\n           ^^^^^^^^^^^^^^^^^^^^^^^^^^^^^^^^^^^\r\n  File \"C:\\Users\\33530\\anaconda3\\Lib\\site-packages\\semgrep\\config_resolver.py\", line 231, in _load_config_from_local_path\r\n    config = [read_config_at_path(loc)]\r\n              ^^^^^^^^^^^^^^^^^^^^^^^^\r\n  File \"C:\\Users\\33530\\anaconda3\\Lib\\site-packages\\semgrep\\config_resolver.py\", line 409, in read_config_at_path\r\n    return ConfigFile(config_id, loc.read_text(), str(loc))\r\n                                 ^^^^^^^^^^^^^^^\r\n  File \"C:\\Users\\33530\\anaconda3\\Lib\\pathlib.py\", line 1028, in read_text\r\n    return f.read()\r\n           ^^^^^^^^\r\nUnicodeDecodeError: 'gbk' codec can't decode byte 0xa5 in position 65: illegal multibyte sequence\r\n"
      },
      {
        "rule": "advanced-taint-analysis.yml",
        "error": "Command failed: semgrep --config=D:\\ide\\tool\\codebase-index\\enhanced-rules\\data-flow\\advanced-taint-analysis.yml D:\\ide\\tool\\codebase-index\\test\\enhanced-semgrep\\test-advanced-taint-analysis.js --json\n[00.08][WARNING](ca-certs): Ignored 1 trust anchors.\r\n'gbk' codec can't decode byte 0xad in position 82: illegal multibyte sequence\r\nTraceback (most recent call last):\r\n  File \"C:\\Users\\33530\\anaconda3\\Lib\\site-packages\\semgrep\\commands\\wrapper.py\", line 51, in wrapper\r\n    func(*args, **kwargs)\r\n  File \"C:\\Users\\33530\\anaconda3\\Lib\\site-packages\\semgrep\\commands\\scan.py\", line 962, in scan\r\n    ) = semgrep.run_scan.run_scan(\r\n        ^^^^^^^^^^^^^^^^^^^^^^^^^^\r\n  File \"C:\\Users\\33530\\anaconda3\\Lib\\site-packages\\semgrep\\tracing.py\", line 294, in inner\r\n    return f(*args, **kwargs)\r\n           ^^^^^^^^^^^^^^^^^^\r\n  File \"C:\\Users\\33530\\anaconda3\\Lib\\site-packages\\semgrep\\run_scan.py\", line 1102, in run_scan\r\n    configs_obj, config_errors = get_config(\r\n                                 ^^^^^^^^^^^\r\n  File \"C:\\Users\\33530\\anaconda3\\Lib\\site-packages\\semgrep\\tracing.py\", line 294, in inner\r\n    return f(*args, **kwargs)\r\n           ^^^^^^^^^^^^^^^^^^\r\n  File \"C:\\Users\\33530\\anaconda3\\Lib\\site-packages\\semgrep\\config_resolver.py\", line 1053, in get_config\r\n    config, errors = Config.from_config_list(\r\n                     ^^^^^^^^^^^^^^^^^^^^^^^^\r\n  File \"C:\\Users\\33530\\anaconda3\\Lib\\site-packages\\semgrep\\tracing.py\", line 294, in inner\r\n    return f(*args, **kwargs)\r\n           ^^^^^^^^^^^^^^^^^^\r\n  File \"C:\\Users\\33530\\anaconda3\\Lib\\site-packages\\semgrep\\config_resolver.py\", line 631, in from_config_list\r\n    resolved_config, config_errors = resolve_config(\r\n                                     ^^^^^^^^^^^^^^^\r\n  File \"C:\\Users\\33530\\anaconda3\\Lib\\site-packages\\semgrep\\tracing.py\", line 294, in inner\r\n    return f(*args, **kwargs)\r\n           ^^^^^^^^^^^^^^^^^^\r\n  File \"C:\\Users\\33530\\anaconda3\\Lib\\site-packages\\semgrep\\config_resolver.py\", line 535, in resolve_config\r\n    config_loader.load_config(),\r\n    ^^^^^^^^^^^^^^^^^^^^^^^^^^^\r\n  File \"C:\\Users\\33530\\anaconda3\\Lib\\site-packages\\semgrep\\config_resolver.py\", line 166, in load_config\r\n    return self._load_config_from_local_path()\r\n           ^^^^^^^^^^^^^^^^^^^^^^^^^^^^^^^^^^^\r\n  File \"C:\\Users\\33530\\anaconda3\\Lib\\site-packages\\semgrep\\config_resolver.py\", line 231, in _load_config_from_local_path\r\n    config = [read_config_at_path(loc)]\r\n              ^^^^^^^^^^^^^^^^^^^^^^^^\r\n  File \"C:\\Users\\33530\\anaconda3\\Lib\\site-packages\\semgrep\\config_resolver.py\", line 409, in read_config_at_path\r\n    return ConfigFile(config_id, loc.read_text(), str(loc))\r\n                                 ^^^^^^^^^^^^^^^\r\n  File \"C:\\Users\\33530\\anaconda3\\Lib\\pathlib.py\", line 1028, in read_text\r\n    return f.read()\r\n           ^^^^^^^^\r\nUnicodeDecodeError: 'gbk' codec can't decode byte 0xad in position 82: illegal multibyte sequence\r\n"
      },
      {
        "rule": "taint-analysis.yml",
        "error": "Command failed: semgrep --config=D:\\ide\\tool\\codebase-index\\enhanced-rules\\data-flow\\taint-analysis.yml D:\\ide\\tool\\codebase-index\\test\\enhanced-semgrep\\test-taint-analysis.js --json\n[00.08][WARNING](ca-certs): Ignored 1 trust anchors.\r\n'gbk' codec can't decode byte 0xab in position 117: illegal multibyte sequence\r\nTraceback (most recent call last):\r\n  File \"C:\\Users\\33530\\anaconda3\\Lib\\site-packages\\semgrep\\commands\\wrapper.py\", line 51, in wrapper\r\n    func(*args, **kwargs)\r\n  File \"C:\\Users\\33530\\anaconda3\\Lib\\site-packages\\semgrep\\commands\\scan.py\", line 962, in scan\r\n    ) = semgrep.run_scan.run_scan(\r\n        ^^^^^^^^^^^^^^^^^^^^^^^^^^\r\n  File \"C:\\Users\\33530\\anaconda3\\Lib\\site-packages\\semgrep\\tracing.py\", line 294, in inner\r\n    return f(*args, **kwargs)\r\n           ^^^^^^^^^^^^^^^^^^\r\n  File \"C:\\Users\\33530\\anaconda3\\Lib\\site-packages\\semgrep\\run_scan.py\", line 1102, in run_scan\r\n    configs_obj, config_errors = get_config(\r\n                                 ^^^^^^^^^^^\r\n  File \"C:\\Users\\33530\\anaconda3\\Lib\\site-packages\\semgrep\\tracing.py\", line 294, in inner\r\n    return f(*args, **kwargs)\r\n           ^^^^^^^^^^^^^^^^^^\r\n  File \"C:\\Users\\33530\\anaconda3\\Lib\\site-packages\\semgrep\\config_resolver.py\", line 1053, in get_config\r\n    config, errors = Config.from_config_list(\r\n                     ^^^^^^^^^^^^^^^^^^^^^^^^\r\n  File \"C:\\Users\\33530\\anaconda3\\Lib\\site-packages\\semgrep\\tracing.py\", line 294, in inner\r\n    return f(*args, **kwargs)\r\n           ^^^^^^^^^^^^^^^^^^\r\n  File \"C:\\Users\\33530\\anaconda3\\Lib\\site-packages\\semgrep\\config_resolver.py\", line 631, in from_config_list\r\n    resolved_config, config_errors = resolve_config(\r\n                                     ^^^^^^^^^^^^^^^\r\n  File \"C:\\Users\\33530\\anaconda3\\Lib\\site-packages\\semgrep\\tracing.py\", line 294, in inner\r\n    return f(*args, **kwargs)\r\n           ^^^^^^^^^^^^^^^^^^\r\n  File \"C:\\Users\\33530\\anaconda3\\Lib\\site-packages\\semgrep\\config_resolver.py\", line 535, in resolve_config\r\n    config_loader.load_config(),\r\n    ^^^^^^^^^^^^^^^^^^^^^^^^^^^\r\n  File \"C:\\Users\\33530\\anaconda3\\Lib\\site-packages\\semgrep\\config_resolver.py\", line 166, in load_config\r\n    return self._load_config_from_local_path()\r\n           ^^^^^^^^^^^^^^^^^^^^^^^^^^^^^^^^^^^\r\n  File \"C:\\Users\\33530\\anaconda3\\Lib\\site-packages\\semgrep\\config_resolver.py\", line 231, in _load_config_from_local_path\r\n    config = [read_config_at_path(loc)]\r\n              ^^^^^^^^^^^^^^^^^^^^^^^^\r\n  File \"C:\\Users\\33530\\anaconda3\\Lib\\site-packages\\semgrep\\config_resolver.py\", line 409, in read_config_at_path\r\n    return ConfigFile(config_id, loc.read_text(), str(loc))\r\n                                 ^^^^^^^^^^^^^^^\r\n  File \"C:\\Users\\33530\\anaconda3\\Lib\\pathlib.py\", line 1028, in read_text\r\n    return f.read()\r\n           ^^^^^^^^\r\nUnicodeDecodeError: 'gbk' codec can't decode byte 0xab in position 117: illegal multibyte sequence\r\n"
      },
      {
        "rule": "authentication-bypass.yml",
        "error": "Command failed: semgrep --config=D:\\ide\\tool\\codebase-index\\enhanced-rules\\security\\authentication-bypass.yml D:\\ide\\tool\\codebase-index\\test\\enhanced-semgrep\\test-authentication-bypass.js --json\n[00.07][WARNING](ca-certs): Ignored 1 trust anchors.\r\n'gbk' codec can't decode byte 0xaa in position 152: illegal multibyte sequence\r\nTraceback (most recent call last):\r\n  File \"C:\\Users\\33530\\anaconda3\\Lib\\site-packages\\semgrep\\commands\\wrapper.py\", line 51, in wrapper\r\n    func(*args, **kwargs)\r\n  File \"C:\\Users\\33530\\anaconda3\\Lib\\site-packages\\semgrep\\commands\\scan.py\", line 962, in scan\r\n    ) = semgrep.run_scan.run_scan(\r\n        ^^^^^^^^^^^^^^^^^^^^^^^^^^\r\n  File \"C:\\Users\\33530\\anaconda3\\Lib\\site-packages\\semgrep\\tracing.py\", line 294, in inner\r\n    return f(*args, **kwargs)\r\n           ^^^^^^^^^^^^^^^^^^\r\n  File \"C:\\Users\\33530\\anaconda3\\Lib\\site-packages\\semgrep\\run_scan.py\", line 1102, in run_scan\r\n    configs_obj, config_errors = get_config(\r\n                                 ^^^^^^^^^^^\r\n  File \"C:\\Users\\33530\\anaconda3\\Lib\\site-packages\\semgrep\\tracing.py\", line 294, in inner\r\n    return f(*args, **kwargs)\r\n           ^^^^^^^^^^^^^^^^^^\r\n  File \"C:\\Users\\33530\\anaconda3\\Lib\\site-packages\\semgrep\\config_resolver.py\", line 1053, in get_config\r\n    config, errors = Config.from_config_list(\r\n                     ^^^^^^^^^^^^^^^^^^^^^^^^\r\n  File \"C:\\Users\\33530\\anaconda3\\Lib\\site-packages\\semgrep\\tracing.py\", line 294, in inner\r\n    return f(*args, **kwargs)\r\n           ^^^^^^^^^^^^^^^^^^\r\n  File \"C:\\Users\\33530\\anaconda3\\Lib\\site-packages\\semgrep\\config_resolver.py\", line 631, in from_config_list\r\n    resolved_config, config_errors = resolve_config(\r\n                                     ^^^^^^^^^^^^^^^\r\n  File \"C:\\Users\\33530\\anaconda3\\Lib\\site-packages\\semgrep\\tracing.py\", line 294, in inner\r\n    return f(*args, **kwargs)\r\n           ^^^^^^^^^^^^^^^^^^\r\n  File \"C:\\Users\\33530\\anaconda3\\Lib\\site-packages\\semgrep\\config_resolver.py\", line 535, in resolve_config\r\n    config_loader.load_config(),\r\n    ^^^^^^^^^^^^^^^^^^^^^^^^^^^\r\n  File \"C:\\Users\\33530\\anaconda3\\Lib\\site-packages\\semgrep\\config_resolver.py\", line 166, in load_config\r\n    return self._load_config_from_local_path()\r\n           ^^^^^^^^^^^^^^^^^^^^^^^^^^^^^^^^^^^\r\n  File \"C:\\Users\\33530\\anaconda3\\Lib\\site-packages\\semgrep\\config_resolver.py\", line 231, in _load_config_from_local_path\r\n    config = [read_config_at_path(loc)]\r\n              ^^^^^^^^^^^^^^^^^^^^^^^^\r\n  File \"C:\\Users\\33530\\anaconda3\\Lib\\site-packages\\semgrep\\config_resolver.py\", line 409, in read_config_at_path\r\n    return ConfigFile(config_id, loc.read_text(), str(loc))\r\n                                 ^^^^^^^^^^^^^^^\r\n  File \"C:\\Users\\33530\\anaconda3\\Lib\\pathlib.py\", line 1028, in read_text\r\n    return f.read()\r\n           ^^^^^^^^\r\nUnicodeDecodeError: 'gbk' codec can't decode byte 0xaa in position 152: illegal multibyte sequence\r\n"
      },
      {
        "rule": "authorization-flaws.yml",
        "error": "Command failed: semgrep --config=D:\\ide\\tool\\codebase-index\\enhanced-rules\\security\\authorization-flaws.yml D:\\ide\\tool\\codebase-index\\test\\enhanced-semgrep\\test-authorization-flaws.js --json\n[00.07][WARNING](ca-certs): Ignored 1 trust anchors.\r\n'gbk' codec can't decode byte 0xaf in position 191: illegal multibyte sequence\r\nTraceback (most recent call last):\r\n  File \"C:\\Users\\33530\\anaconda3\\Lib\\site-packages\\semgrep\\commands\\wrapper.py\", line 51, in wrapper\r\n    func(*args, **kwargs)\r\n  File \"C:\\Users\\33530\\anaconda3\\Lib\\site-packages\\semgrep\\commands\\scan.py\", line 962, in scan\r\n    ) = semgrep.run_scan.run_scan(\r\n        ^^^^^^^^^^^^^^^^^^^^^^^^^^\r\n  File \"C:\\Users\\33530\\anaconda3\\Lib\\site-packages\\semgrep\\tracing.py\", line 294, in inner\r\n    return f(*args, **kwargs)\r\n           ^^^^^^^^^^^^^^^^^^\r\n  File \"C:\\Users\\33530\\anaconda3\\Lib\\site-packages\\semgrep\\run_scan.py\", line 1102, in run_scan\r\n    configs_obj, config_errors = get_config(\r\n                                 ^^^^^^^^^^^\r\n  File \"C:\\Users\\33530\\anaconda3\\Lib\\site-packages\\semgrep\\tracing.py\", line 294, in inner\r\n    return f(*args, **kwargs)\r\n           ^^^^^^^^^^^^^^^^^^\r\n  File \"C:\\Users\\33530\\anaconda3\\Lib\\site-packages\\semgrep\\config_resolver.py\", line 1053, in get_config\r\n    config, errors = Config.from_config_list(\r\n                     ^^^^^^^^^^^^^^^^^^^^^^^^\r\n  File \"C:\\Users\\33530\\anaconda3\\Lib\\site-packages\\semgrep\\tracing.py\", line 294, in inner\r\n    return f(*args, **kwargs)\r\n           ^^^^^^^^^^^^^^^^^^\r\n  File \"C:\\Users\\33530\\anaconda3\\Lib\\site-packages\\semgrep\\config_resolver.py\", line 631, in from_config_list\r\n    resolved_config, config_errors = resolve_config(\r\n                                     ^^^^^^^^^^^^^^^\r\n  File \"C:\\Users\\33530\\anaconda3\\Lib\\site-packages\\semgrep\\tracing.py\", line 294, in inner\r\n    return f(*args, **kwargs)\r\n           ^^^^^^^^^^^^^^^^^^\r\n  File \"C:\\Users\\33530\\anaconda3\\Lib\\site-packages\\semgrep\\config_resolver.py\", line 535, in resolve_config\r\n    config_loader.load_config(),\r\n    ^^^^^^^^^^^^^^^^^^^^^^^^^^^\r\n  File \"C:\\Users\\33530\\anaconda3\\Lib\\site-packages\\semgrep\\config_resolver.py\", line 166, in load_config\r\n    return self._load_config_from_local_path()\r\n           ^^^^^^^^^^^^^^^^^^^^^^^^^^^^^^^^^^^\r\n  File \"C:\\Users\\33530\\anaconda3\\Lib\\site-packages\\semgrep\\config_resolver.py\", line 231, in _load_config_from_local_path\r\n    config = [read_config_at_path(loc)]\r\n              ^^^^^^^^^^^^^^^^^^^^^^^^\r\n  File \"C:\\Users\\33530\\anaconda3\\Lib\\site-packages\\semgrep\\config_resolver.py\", line 409, in read_config_at_path\r\n    return ConfigFile(config_id, loc.read_text(), str(loc))\r\n                                 ^^^^^^^^^^^^^^^\r\n  File \"C:\\Users\\33530\\anaconda3\\Lib\\pathlib.py\", line 1028, in read_text\r\n    return f.read()\r\n           ^^^^^^^^\r\nUnicodeDecodeError: 'gbk' codec can't decode byte 0xaf in position 191: illegal multibyte sequence\r\n"
      },
      {
        "rule": "command-injection.yml",
        "error": "Command failed: semgrep --config=D:\\ide\\tool\\codebase-index\\enhanced-rules\\security\\command-injection.yml D:\\ide\\tool\\codebase-index\\test\\enhanced-semgrep\\test-command-injection.js --json\n[00.08][WARNING](ca-certs): Ignored 1 trust anchors.\r\n'gbk' codec can't decode byte 0xa4 in position 148: illegal multibyte sequence\r\nTraceback (most recent call last):\r\n  File \"C:\\Users\\33530\\anaconda3\\Lib\\site-packages\\semgrep\\commands\\wrapper.py\", line 51, in wrapper\r\n    func(*args, **kwargs)\r\n  File \"C:\\Users\\33530\\anaconda3\\Lib\\site-packages\\semgrep\\commands\\scan.py\", line 962, in scan\r\n    ) = semgrep.run_scan.run_scan(\r\n        ^^^^^^^^^^^^^^^^^^^^^^^^^^\r\n  File \"C:\\Users\\33530\\anaconda3\\Lib\\site-packages\\semgrep\\tracing.py\", line 294, in inner\r\n    return f(*args, **kwargs)\r\n           ^^^^^^^^^^^^^^^^^^\r\n  File \"C:\\Users\\33530\\anaconda3\\Lib\\site-packages\\semgrep\\run_scan.py\", line 1102, in run_scan\r\n    configs_obj, config_errors = get_config(\r\n                                 ^^^^^^^^^^^\r\n  File \"C:\\Users\\33530\\anaconda3\\Lib\\site-packages\\semgrep\\tracing.py\", line 294, in inner\r\n    return f(*args, **kwargs)\r\n           ^^^^^^^^^^^^^^^^^^\r\n  File \"C:\\Users\\33530\\anaconda3\\Lib\\site-packages\\semgrep\\config_resolver.py\", line 1053, in get_config\r\n    config, errors = Config.from_config_list(\r\n                     ^^^^^^^^^^^^^^^^^^^^^^^^\r\n  File \"C:\\Users\\33530\\anaconda3\\Lib\\site-packages\\semgrep\\tracing.py\", line 294, in inner\r\n    return f(*args, **kwargs)\r\n           ^^^^^^^^^^^^^^^^^^\r\n  File \"C:\\Users\\33530\\anaconda3\\Lib\\site-packages\\semgrep\\config_resolver.py\", line 631, in from_config_list\r\n    resolved_config, config_errors = resolve_config(\r\n                                     ^^^^^^^^^^^^^^^\r\n  File \"C:\\Users\\33530\\anaconda3\\Lib\\site-packages\\semgrep\\tracing.py\", line 294, in inner\r\n    return f(*args, **kwargs)\r\n           ^^^^^^^^^^^^^^^^^^\r\n  File \"C:\\Users\\33530\\anaconda3\\Lib\\site-packages\\semgrep\\config_resolver.py\", line 535, in resolve_config\r\n    config_loader.load_config(),\r\n    ^^^^^^^^^^^^^^^^^^^^^^^^^^^\r\n  File \"C:\\Users\\33530\\anaconda3\\Lib\\site-packages\\semgrep\\config_resolver.py\", line 166, in load_config\r\n    return self._load_config_from_local_path()\r\n           ^^^^^^^^^^^^^^^^^^^^^^^^^^^^^^^^^^^\r\n  File \"C:\\Users\\33530\\anaconda3\\Lib\\site-packages\\semgrep\\config_resolver.py\", line 231, in _load_config_from_local_path\r\n    config = [read_config_at_path(loc)]\r\n              ^^^^^^^^^^^^^^^^^^^^^^^^\r\n  File \"C:\\Users\\33530\\anaconda3\\Lib\\site-packages\\semgrep\\config_resolver.py\", line 409, in read_config_at_path\r\n    return ConfigFile(config_id, loc.read_text(), str(loc))\r\n                                 ^^^^^^^^^^^^^^^\r\n  File \"C:\\Users\\33530\\anaconda3\\Lib\\pathlib.py\", line 1028, in read_text\r\n    return f.read()\r\n           ^^^^^^^^\r\nUnicodeDecodeError: 'gbk' codec can't decode byte 0xa4 in position 148: illegal multibyte sequence\r\n"
      },
      {
        "rule": "comprehensive-security-rules.yml",
        "error": "Command failed: semgrep --config=D:\\ide\\tool\\codebase-index\\enhanced-rules\\security\\comprehensive-security-rules.yml D:\\ide\\tool\\codebase-index\\test\\enhanced-semgrep\\test-comprehensive-security-rules.js --json\n[00.07][WARNING](ca-certs): Ignored 1 trust anchors.\r\n'gbk' codec can't decode byte 0x80 in position 79: illegal multibyte sequence\r\nTraceback (most recent call last):\r\n  File \"C:\\Users\\33530\\anaconda3\\Lib\\site-packages\\semgrep\\commands\\wrapper.py\", line 51, in wrapper\r\n    func(*args, **kwargs)\r\n  File \"C:\\Users\\33530\\anaconda3\\Lib\\site-packages\\semgrep\\commands\\scan.py\", line 962, in scan\r\n    ) = semgrep.run_scan.run_scan(\r\n        ^^^^^^^^^^^^^^^^^^^^^^^^^^\r\n  File \"C:\\Users\\33530\\anaconda3\\Lib\\site-packages\\semgrep\\tracing.py\", line 294, in inner\r\n    return f(*args, **kwargs)\r\n           ^^^^^^^^^^^^^^^^^^\r\n  File \"C:\\Users\\33530\\anaconda3\\Lib\\site-packages\\semgrep\\run_scan.py\", line 1102, in run_scan\r\n    configs_obj, config_errors = get_config(\r\n                                 ^^^^^^^^^^^\r\n  File \"C:\\Users\\33530\\anaconda3\\Lib\\site-packages\\semgrep\\tracing.py\", line 294, in inner\r\n    return f(*args, **kwargs)\r\n           ^^^^^^^^^^^^^^^^^^\r\n  File \"C:\\Users\\33530\\anaconda3\\Lib\\site-packages\\semgrep\\config_resolver.py\", line 1053, in get_config\r\n    config, errors = Config.from_config_list(\r\n                     ^^^^^^^^^^^^^^^^^^^^^^^^\r\n  File \"C:\\Users\\33530\\anaconda3\\Lib\\site-packages\\semgrep\\tracing.py\", line 294, in inner\r\n    return f(*args, **kwargs)\r\n           ^^^^^^^^^^^^^^^^^^\r\n  File \"C:\\Users\\33530\\anaconda3\\Lib\\site-packages\\semgrep\\config_resolver.py\", line 631, in from_config_list\r\n    resolved_config, config_errors = resolve_config(\r\n                                     ^^^^^^^^^^^^^^^\r\n  File \"C:\\Users\\33530\\anaconda3\\Lib\\site-packages\\semgrep\\tracing.py\", line 294, in inner\r\n    return f(*args, **kwargs)\r\n           ^^^^^^^^^^^^^^^^^^\r\n  File \"C:\\Users\\33530\\anaconda3\\Lib\\site-packages\\semgrep\\config_resolver.py\", line 535, in resolve_config\r\n    config_loader.load_config(),\r\n    ^^^^^^^^^^^^^^^^^^^^^^^^^^^\r\n  File \"C:\\Users\\33530\\anaconda3\\Lib\\site-packages\\semgrep\\config_resolver.py\", line 166, in load_config\r\n    return self._load_config_from_local_path()\r\n           ^^^^^^^^^^^^^^^^^^^^^^^^^^^^^^^^^^^\r\n  File \"C:\\Users\\33530\\anaconda3\\Lib\\site-packages\\semgrep\\config_resolver.py\", line 231, in _load_config_from_local_path\r\n    config = [read_config_at_path(loc)]\r\n              ^^^^^^^^^^^^^^^^^^^^^^^^\r\n  File \"C:\\Users\\33530\\anaconda3\\Lib\\site-packages\\semgrep\\config_resolver.py\", line 409, in read_config_at_path\r\n    return ConfigFile(config_id, loc.read_text(), str(loc))\r\n                                 ^^^^^^^^^^^^^^^\r\n  File \"C:\\Users\\33530\\anaconda3\\Lib\\pathlib.py\", line 1028, in read_text\r\n    return f.read()\r\n           ^^^^^^^^\r\nUnicodeDecodeError: 'gbk' codec can't decode byte 0x80 in position 79: illegal multibyte sequence\r\n"
      },
      {
        "rule": "cryptographic-issues.yml",
        "error": "Command failed: semgrep --config=D:\\ide\\tool\\codebase-index\\enhanced-rules\\security\\cryptographic-issues.yml D:\\ide\\tool\\codebase-index\\test\\enhanced-semgrep\\test-cryptographic-issues.js --json\n[00.07][WARNING](ca-certs): Ignored 1 trust anchors.\r\n'gbk' codec can't decode byte 0xae in position 128: illegal multibyte sequence\r\nTraceback (most recent call last):\r\n  File \"C:\\Users\\33530\\anaconda3\\Lib\\site-packages\\semgrep\\commands\\wrapper.py\", line 51, in wrapper\r\n    func(*args, **kwargs)\r\n  File \"C:\\Users\\33530\\anaconda3\\Lib\\site-packages\\semgrep\\commands\\scan.py\", line 962, in scan\r\n    ) = semgrep.run_scan.run_scan(\r\n        ^^^^^^^^^^^^^^^^^^^^^^^^^^\r\n  File \"C:\\Users\\33530\\anaconda3\\Lib\\site-packages\\semgrep\\tracing.py\", line 294, in inner\r\n    return f(*args, **kwargs)\r\n           ^^^^^^^^^^^^^^^^^^\r\n  File \"C:\\Users\\33530\\anaconda3\\Lib\\site-packages\\semgrep\\run_scan.py\", line 1102, in run_scan\r\n    configs_obj, config_errors = get_config(\r\n                                 ^^^^^^^^^^^\r\n  File \"C:\\Users\\33530\\anaconda3\\Lib\\site-packages\\semgrep\\tracing.py\", line 294, in inner\r\n    return f(*args, **kwargs)\r\n           ^^^^^^^^^^^^^^^^^^\r\n  File \"C:\\Users\\33530\\anaconda3\\Lib\\site-packages\\semgrep\\config_resolver.py\", line 1053, in get_config\r\n    config, errors = Config.from_config_list(\r\n                     ^^^^^^^^^^^^^^^^^^^^^^^^\r\n  File \"C:\\Users\\33530\\anaconda3\\Lib\\site-packages\\semgrep\\tracing.py\", line 294, in inner\r\n    return f(*args, **kwargs)\r\n           ^^^^^^^^^^^^^^^^^^\r\n  File \"C:\\Users\\33530\\anaconda3\\Lib\\site-packages\\semgrep\\config_resolver.py\", line 631, in from_config_list\r\n    resolved_config, config_errors = resolve_config(\r\n                                     ^^^^^^^^^^^^^^^\r\n  File \"C:\\Users\\33530\\anaconda3\\Lib\\site-packages\\semgrep\\tracing.py\", line 294, in inner\r\n    return f(*args, **kwargs)\r\n           ^^^^^^^^^^^^^^^^^^\r\n  File \"C:\\Users\\33530\\anaconda3\\Lib\\site-packages\\semgrep\\config_resolver.py\", line 535, in resolve_config\r\n    config_loader.load_config(),\r\n    ^^^^^^^^^^^^^^^^^^^^^^^^^^^\r\n  File \"C:\\Users\\33530\\anaconda3\\Lib\\site-packages\\semgrep\\config_resolver.py\", line 166, in load_config\r\n    return self._load_config_from_local_path()\r\n           ^^^^^^^^^^^^^^^^^^^^^^^^^^^^^^^^^^^\r\n  File \"C:\\Users\\33530\\anaconda3\\Lib\\site-packages\\semgrep\\config_resolver.py\", line 231, in _load_config_from_local_path\r\n    config = [read_config_at_path(loc)]\r\n              ^^^^^^^^^^^^^^^^^^^^^^^^\r\n  File \"C:\\Users\\33530\\anaconda3\\Lib\\site-packages\\semgrep\\config_resolver.py\", line 409, in read_config_at_path\r\n    return ConfigFile(config_id, loc.read_text(), str(loc))\r\n                                 ^^^^^^^^^^^^^^^\r\n  File \"C:\\Users\\33530\\anaconda3\\Lib\\pathlib.py\", line 1028, in read_text\r\n    return f.read()\r\n           ^^^^^^^^\r\nUnicodeDecodeError: 'gbk' codec can't decode byte 0xae in position 128: illegal multibyte sequence\r\n"
      },
      {
        "rule": "insecure-deserialization.yml",
        "error": "Command failed: semgrep --config=D:\\ide\\tool\\codebase-index\\enhanced-rules\\security\\insecure-deserialization.yml D:\\ide\\tool\\codebase-index\\test\\enhanced-semgrep\\test-insecure-deserialization.js --json\n[00.07][WARNING](ca-certs): Ignored 1 trust anchors.\r\n'gbk' codec can't decode byte 0x96 in position 164: illegal multibyte sequence\r\nTraceback (most recent call last):\r\n  File \"C:\\Users\\33530\\anaconda3\\Lib\\site-packages\\semgrep\\commands\\wrapper.py\", line 51, in wrapper\r\n    func(*args, **kwargs)\r\n  File \"C:\\Users\\33530\\anaconda3\\Lib\\site-packages\\semgrep\\commands\\scan.py\", line 962, in scan\r\n    ) = semgrep.run_scan.run_scan(\r\n        ^^^^^^^^^^^^^^^^^^^^^^^^^^\r\n  File \"C:\\Users\\33530\\anaconda3\\Lib\\site-packages\\semgrep\\tracing.py\", line 294, in inner\r\n    return f(*args, **kwargs)\r\n           ^^^^^^^^^^^^^^^^^^\r\n  File \"C:\\Users\\33530\\anaconda3\\Lib\\site-packages\\semgrep\\run_scan.py\", line 1102, in run_scan\r\n    configs_obj, config_errors = get_config(\r\n                                 ^^^^^^^^^^^\r\n  File \"C:\\Users\\33530\\anaconda3\\Lib\\site-packages\\semgrep\\tracing.py\", line 294, in inner\r\n    return f(*args, **kwargs)\r\n           ^^^^^^^^^^^^^^^^^^\r\n  File \"C:\\Users\\33530\\anaconda3\\Lib\\site-packages\\semgrep\\config_resolver.py\", line 1053, in get_config\r\n    config, errors = Config.from_config_list(\r\n                     ^^^^^^^^^^^^^^^^^^^^^^^^\r\n  File \"C:\\Users\\33530\\anaconda3\\Lib\\site-packages\\semgrep\\tracing.py\", line 294, in inner\r\n    return f(*args, **kwargs)\r\n           ^^^^^^^^^^^^^^^^^^\r\n  File \"C:\\Users\\33530\\anaconda3\\Lib\\site-packages\\semgrep\\config_resolver.py\", line 631, in from_config_list\r\n    resolved_config, config_errors = resolve_config(\r\n                                     ^^^^^^^^^^^^^^^\r\n  File \"C:\\Users\\33530\\anaconda3\\Lib\\site-packages\\semgrep\\tracing.py\", line 294, in inner\r\n    return f(*args, **kwargs)\r\n           ^^^^^^^^^^^^^^^^^^\r\n  File \"C:\\Users\\33530\\anaconda3\\Lib\\site-packages\\semgrep\\config_resolver.py\", line 535, in resolve_config\r\n    config_loader.load_config(),\r\n    ^^^^^^^^^^^^^^^^^^^^^^^^^^^\r\n  File \"C:\\Users\\33530\\anaconda3\\Lib\\site-packages\\semgrep\\config_resolver.py\", line 166, in load_config\r\n    return self._load_config_from_local_path()\r\n           ^^^^^^^^^^^^^^^^^^^^^^^^^^^^^^^^^^^\r\n  File \"C:\\Users\\33530\\anaconda3\\Lib\\site-packages\\semgrep\\config_resolver.py\", line 231, in _load_config_from_local_path\r\n    config = [read_config_at_path(loc)]\r\n              ^^^^^^^^^^^^^^^^^^^^^^^^\r\n  File \"C:\\Users\\33530\\anaconda3\\Lib\\site-packages\\semgrep\\config_resolver.py\", line 409, in read_config_at_path\r\n    return ConfigFile(config_id, loc.read_text(), str(loc))\r\n                                 ^^^^^^^^^^^^^^^\r\n  File \"C:\\Users\\33530\\anaconda3\\Lib\\pathlib.py\", line 1028, in read_text\r\n    return f.read()\r\n           ^^^^^^^^\r\nUnicodeDecodeError: 'gbk' codec can't decode byte 0x96 in position 164: illegal multibyte sequence\r\n"
      },
      {
        "rule": "path-traversal.yml",
        "error": "Command failed: semgrep --config=D:\\ide\\tool\\codebase-index\\enhanced-rules\\security\\path-traversal.yml D:\\ide\\tool\\codebase-index\\test\\enhanced-semgrep\\test-path-traversal.js --json\n[00.09][WARNING](ca-certs): Ignored 1 trust anchors.\r\n'gbk' codec can't decode byte 0xaf in position 115: illegal multibyte sequence\r\nTraceback (most recent call last):\r\n  File \"C:\\Users\\33530\\anaconda3\\Lib\\site-packages\\semgrep\\commands\\wrapper.py\", line 51, in wrapper\r\n    func(*args, **kwargs)\r\n  File \"C:\\Users\\33530\\anaconda3\\Lib\\site-packages\\semgrep\\commands\\scan.py\", line 962, in scan\r\n    ) = semgrep.run_scan.run_scan(\r\n        ^^^^^^^^^^^^^^^^^^^^^^^^^^\r\n  File \"C:\\Users\\33530\\anaconda3\\Lib\\site-packages\\semgrep\\tracing.py\", line 294, in inner\r\n    return f(*args, **kwargs)\r\n           ^^^^^^^^^^^^^^^^^^\r\n  File \"C:\\Users\\33530\\anaconda3\\Lib\\site-packages\\semgrep\\run_scan.py\", line 1102, in run_scan\r\n    configs_obj, config_errors = get_config(\r\n                                 ^^^^^^^^^^^\r\n  File \"C:\\Users\\33530\\anaconda3\\Lib\\site-packages\\semgrep\\tracing.py\", line 294, in inner\r\n    return f(*args, **kwargs)\r\n           ^^^^^^^^^^^^^^^^^^\r\n  File \"C:\\Users\\33530\\anaconda3\\Lib\\site-packages\\semgrep\\config_resolver.py\", line 1053, in get_config\r\n    config, errors = Config.from_config_list(\r\n                     ^^^^^^^^^^^^^^^^^^^^^^^^\r\n  File \"C:\\Users\\33530\\anaconda3\\Lib\\site-packages\\semgrep\\tracing.py\", line 294, in inner\r\n    return f(*args, **kwargs)\r\n           ^^^^^^^^^^^^^^^^^^\r\n  File \"C:\\Users\\33530\\anaconda3\\Lib\\site-packages\\semgrep\\config_resolver.py\", line 631, in from_config_list\r\n    resolved_config, config_errors = resolve_config(\r\n                                     ^^^^^^^^^^^^^^^\r\n  File \"C:\\Users\\33530\\anaconda3\\Lib\\site-packages\\semgrep\\tracing.py\", line 294, in inner\r\n    return f(*args, **kwargs)\r\n           ^^^^^^^^^^^^^^^^^^\r\n  File \"C:\\Users\\33530\\anaconda3\\Lib\\site-packages\\semgrep\\config_resolver.py\", line 535, in resolve_config\r\n    config_loader.load_config(),\r\n    ^^^^^^^^^^^^^^^^^^^^^^^^^^^\r\n  File \"C:\\Users\\33530\\anaconda3\\Lib\\site-packages\\semgrep\\config_resolver.py\", line 166, in load_config\r\n    return self._load_config_from_local_path()\r\n           ^^^^^^^^^^^^^^^^^^^^^^^^^^^^^^^^^^^\r\n  File \"C:\\Users\\33530\\anaconda3\\Lib\\site-packages\\semgrep\\config_resolver.py\", line 231, in _load_config_from_local_path\r\n    config = [read_config_at_path(loc)]\r\n              ^^^^^^^^^^^^^^^^^^^^^^^^\r\n  File \"C:\\Users\\33530\\anaconda3\\Lib\\site-packages\\semgrep\\config_resolver.py\", line 409, in read_config_at_path\r\n    return ConfigFile(config_id, loc.read_text(), str(loc))\r\n                                 ^^^^^^^^^^^^^^^\r\n  File \"C:\\Users\\33530\\anaconda3\\Lib\\pathlib.py\", line 1028, in read_text\r\n    return f.read()\r\n           ^^^^^^^^\r\nUnicodeDecodeError: 'gbk' codec can't decode byte 0xaf in position 115: illegal multibyte sequence\r\n"
      },
      {
        "rule": "sql-injection.yml",
        "error": "Command failed: semgrep --config=D:\\ide\\tool\\codebase-index\\enhanced-rules\\security\\sql-injection.yml D:\\ide\\tool\\codebase-index\\test\\enhanced-semgrep\\test-sql-injection.js --json\n[00.08][WARNING](ca-certs): Ignored 1 trust anchors.\r\n'gbk' codec can't decode byte 0xaf in position 193: illegal multibyte sequence\r\nTraceback (most recent call last):\r\n  File \"C:\\Users\\33530\\anaconda3\\Lib\\site-packages\\semgrep\\commands\\wrapper.py\", line 51, in wrapper\r\n    func(*args, **kwargs)\r\n  File \"C:\\Users\\33530\\anaconda3\\Lib\\site-packages\\semgrep\\commands\\scan.py\", line 962, in scan\r\n    ) = semgrep.run_scan.run_scan(\r\n        ^^^^^^^^^^^^^^^^^^^^^^^^^^\r\n  File \"C:\\Users\\33530\\anaconda3\\Lib\\site-packages\\semgrep\\tracing.py\", line 294, in inner\r\n    return f(*args, **kwargs)\r\n           ^^^^^^^^^^^^^^^^^^\r\n  File \"C:\\Users\\33530\\anaconda3\\Lib\\site-packages\\semgrep\\run_scan.py\", line 1102, in run_scan\r\n    configs_obj, config_errors = get_config(\r\n                                 ^^^^^^^^^^^\r\n  File \"C:\\Users\\33530\\anaconda3\\Lib\\site-packages\\semgrep\\tracing.py\", line 294, in inner\r\n    return f(*args, **kwargs)\r\n           ^^^^^^^^^^^^^^^^^^\r\n  File \"C:\\Users\\33530\\anaconda3\\Lib\\site-packages\\semgrep\\config_resolver.py\", line 1053, in get_config\r\n    config, errors = Config.from_config_list(\r\n                     ^^^^^^^^^^^^^^^^^^^^^^^^\r\n  File \"C:\\Users\\33530\\anaconda3\\Lib\\site-packages\\semgrep\\tracing.py\", line 294, in inner\r\n    return f(*args, **kwargs)\r\n           ^^^^^^^^^^^^^^^^^^\r\n  File \"C:\\Users\\33530\\anaconda3\\Lib\\site-packages\\semgrep\\config_resolver.py\", line 631, in from_config_list\r\n    resolved_config, config_errors = resolve_config(\r\n                                     ^^^^^^^^^^^^^^^\r\n  File \"C:\\Users\\33530\\anaconda3\\Lib\\site-packages\\semgrep\\tracing.py\", line 294, in inner\r\n    return f(*args, **kwargs)\r\n           ^^^^^^^^^^^^^^^^^^\r\n  File \"C:\\Users\\33530\\anaconda3\\Lib\\site-packages\\semgrep\\config_resolver.py\", line 535, in resolve_config\r\n    config_loader.load_config(),\r\n    ^^^^^^^^^^^^^^^^^^^^^^^^^^^\r\n  File \"C:\\Users\\33530\\anaconda3\\Lib\\site-packages\\semgrep\\config_resolver.py\", line 166, in load_config\r\n    return self._load_config_from_local_path()\r\n           ^^^^^^^^^^^^^^^^^^^^^^^^^^^^^^^^^^^\r\n  File \"C:\\Users\\33530\\anaconda3\\Lib\\site-packages\\semgrep\\config_resolver.py\", line 231, in _load_config_from_local_path\r\n    config = [read_config_at_path(loc)]\r\n              ^^^^^^^^^^^^^^^^^^^^^^^^\r\n  File \"C:\\Users\\33530\\anaconda3\\Lib\\site-packages\\semgrep\\config_resolver.py\", line 409, in read_config_at_path\r\n    return ConfigFile(config_id, loc.read_text(), str(loc))\r\n                                 ^^^^^^^^^^^^^^^\r\n  File \"C:\\Users\\33530\\anaconda3\\Lib\\pathlib.py\", line 1028, in read_text\r\n    return f.read()\r\n           ^^^^^^^^\r\nUnicodeDecodeError: 'gbk' codec can't decode byte 0xaf in position 193: illegal multibyte sequence\r\n"
      },
      {
        "rule": "xss-detection.yml",
        "error": "Command failed: semgrep --config=D:\\ide\\tool\\codebase-index\\enhanced-rules\\security\\xss-detection.yml D:\\ide\\tool\\codebase-index\\test\\enhanced-semgrep\\test-xss-detection.js --json\n[00.07][WARNING](ca-certs): Ignored 1 trust anchors.\r\n'gbk' codec can't decode byte 0xae in position 149: illegal multibyte sequence\r\nTraceback (most recent call last):\r\n  File \"C:\\Users\\33530\\anaconda3\\Lib\\site-packages\\semgrep\\commands\\wrapper.py\", line 51, in wrapper\r\n    func(*args, **kwargs)\r\n  File \"C:\\Users\\33530\\anaconda3\\Lib\\site-packages\\semgrep\\commands\\scan.py\", line 962, in scan\r\n    ) = semgrep.run_scan.run_scan(\r\n        ^^^^^^^^^^^^^^^^^^^^^^^^^^\r\n  File \"C:\\Users\\33530\\anaconda3\\Lib\\site-packages\\semgrep\\tracing.py\", line 294, in inner\r\n    return f(*args, **kwargs)\r\n           ^^^^^^^^^^^^^^^^^^\r\n  File \"C:\\Users\\33530\\anaconda3\\Lib\\site-packages\\semgrep\\run_scan.py\", line 1102, in run_scan\r\n    configs_obj, config_errors = get_config(\r\n                                 ^^^^^^^^^^^\r\n  File \"C:\\Users\\33530\\anaconda3\\Lib\\site-packages\\semgrep\\tracing.py\", line 294, in inner\r\n    return f(*args, **kwargs)\r\n           ^^^^^^^^^^^^^^^^^^\r\n  File \"C:\\Users\\33530\\anaconda3\\Lib\\site-packages\\semgrep\\config_resolver.py\", line 1053, in get_config\r\n    config, errors = Config.from_config_list(\r\n                     ^^^^^^^^^^^^^^^^^^^^^^^^\r\n  File \"C:\\Users\\33530\\anaconda3\\Lib\\site-packages\\semgrep\\tracing.py\", line 294, in inner\r\n    return f(*args, **kwargs)\r\n           ^^^^^^^^^^^^^^^^^^\r\n  File \"C:\\Users\\33530\\anaconda3\\Lib\\site-packages\\semgrep\\config_resolver.py\", line 631, in from_config_list\r\n    resolved_config, config_errors = resolve_config(\r\n                                     ^^^^^^^^^^^^^^^\r\n  File \"C:\\Users\\33530\\anaconda3\\Lib\\site-packages\\semgrep\\tracing.py\", line 294, in inner\r\n    return f(*args, **kwargs)\r\n           ^^^^^^^^^^^^^^^^^^\r\n  File \"C:\\Users\\33530\\anaconda3\\Lib\\site-packages\\semgrep\\config_resolver.py\", line 535, in resolve_config\r\n    config_loader.load_config(),\r\n    ^^^^^^^^^^^^^^^^^^^^^^^^^^^\r\n  File \"C:\\Users\\33530\\anaconda3\\Lib\\site-packages\\semgrep\\config_resolver.py\", line 166, in load_config\r\n    return self._load_config_from_local_path()\r\n           ^^^^^^^^^^^^^^^^^^^^^^^^^^^^^^^^^^^\r\n  File \"C:\\Users\\33530\\anaconda3\\Lib\\site-packages\\semgrep\\config_resolver.py\", line 231, in _load_config_from_local_path\r\n    config = [read_config_at_path(loc)]\r\n              ^^^^^^^^^^^^^^^^^^^^^^^^\r\n  File \"C:\\Users\\33530\\anaconda3\\Lib\\site-packages\\semgrep\\config_resolver.py\", line 409, in read_config_at_path\r\n    return ConfigFile(config_id, loc.read_text(), str(loc))\r\n                                 ^^^^^^^^^^^^^^^\r\n  File \"C:\\Users\\33530\\anaconda3\\Lib\\pathlib.py\", line 1028, in read_text\r\n    return f.read()\r\n           ^^^^^^^^\r\nUnicodeDecodeError: 'gbk' codec can't decode byte 0xae in position 149: illegal multibyte sequence\r\n"
      }
    ]
  }
}